<?xml version="1.0" encoding="utf-8"?>
<!-- This URDF was automatically created by SolidWorks to URDF Exporter! Originally created by Stephen Brawner (brawner@gmail.com) 
     Commit Version: 1.6.0-4-g7f85cfe  Build Version: 1.6.7995.38578
     For more information, please see http://wiki.ros.org/sw_urdf_exporter -->
<robot
  name="planar_robot">
  <link name="dummy_link"/>
  <joint name="joint_dummy" type="fixed">
    <parent link="dummy_link" />
    <child link="base_link" />
  </joint>
  <link
    name="base_link">
    <inertial>
      <origin
        xyz="0.0016724 -0.025 3.5912E-19"
        rpy="0 0 0" />
      <mass
        value="0.40539" />
      <inertia
        ixx="0.00033091"
        ixy="5.152E-21"
        ixz="-6.8519E-21"
        iyy="0.00052707"
        iyz="-7.2766E-22"
        izz="0.00036507" />
    </inertial>
    <visual>
      <origin
        xyz="0 0 0"
        rpy="0 0 0" />
      <geometry>
        <mesh
          filename="package://planar_robot/meshes/base_link.STL" />
      </geometry>
      <material
        name="">
        <color
          rgba="1 0.8 0.5 1" />
      </material>
    </visual>
    <collision>
      <origin
        xyz="0 0 0"
        rpy="0 0 0" />
      <geometry>
        <mesh
          filename="package://planar_robot/meshes/base_link.STL" />
      </geometry>
    </collision>
  </link>
  <link
    name="link_1">
    <inertial>
      <origin
        xyz="0.25 0.019411 -6.9389E-17"
        rpy="0 0 0" />
      <mass
        value="1.7395" />
      <inertia
        ixx="0.0010806"
        ixy="1.6333E-19"
        ixz="9.1886E-18"
        iyy="0.046641"
        iyz="8.3906E-21"
        izz="0.046004" />
    </inertial>
    <visual>
      <origin
        xyz="0 0 0"
        rpy="0 0 0" />
      <geometry>
        <mesh
          filename="package://planar_robot/meshes/link_1.STL" />
      </geometry>
      <material
        name="">
        <color
          rgba="1 1 1 1" />
      </material>
    </visual>
    <collision>
      <origin
        xyz="0 0 0"
        rpy="0 0 0" />
      <geometry>
        <mesh
          filename="package://planar_robot/meshes/link_1.STL" />
      </geometry>
    </collision>
  </link>
  <joint
    name="joint_1"
    type="continuous">
    <origin
      xyz="0 0 0"
      rpy="1.5708 0 0" />
    <parent
      link="base_link" />
    <child
      link="link_1" />
    <axis
      xyz="0 1 0" />
    <limit
      lower="-6.28"
      upper="6.28"
      effort="0"
      velocity="0" />
  </joint>
  <link
    name="link_2">
    <inertial>
      <origin
        xyz="0.2 0.012299 -1.6653E-16"
        rpy="0 0 0" />
      <mass
        value="0.65846" />
      <inertia
        ixx="0.00022042"
        ixy="7.022E-20"
        ixz="1.1791E-17"
        iyy="0.011151"
        iyz="7.0855E-21"
        izz="0.010997" />
    </inertial>
    <visual>
      <origin
        xyz="0 0 0"
        rpy="0 0 0" />
      <geometry>
        <mesh
          filename="package://planar_robot/meshes/link_2.STL" />
      </geometry>
      <material
        name="">
        <color
          rgba="0.8 1 1 1" />
      </material>
    </visual>
    <collision>
      <origin
        xyz="0 0 0"
        rpy="0 0 0" />
      <geometry>
        <mesh
          filename="package://planar_robot/meshes/link_2.STL" />
      </geometry>
    </collision>
  </link>
  <joint
    name="joint_2"
    type="continuous">
    <origin
      xyz="0.5 0.04 0"
      rpy="0 0 0" />
    <parent
      link="link_1" />
    <child
      link="link_2" />
    <axis
      xyz="0 1 0" />
    <limit
      lower="-6.28"
      upper="6.28"
      effort="0"
      velocity="0" />
  </joint>
  <link
    name="link_3">
    <inertial>
      <origin
        xyz="0.05 -0.012263 0"
        rpy="0 0 0" />
      <mass
        value="0.21596" />
      <inertia
        ixx="6.8918E-05"
        ixy="-3.2388E-21"
        ixz="3.1848E-19"
        iyy="0.00045305"
        iyz="-5.6311E-22"
        izz="0.00040598" />
    </inertial>
    <visual>
      <origin
        xyz="0 0 0"
        rpy="0 0 0" />
      <geometry>
        <mesh
          filename="package://planar_robot/meshes/link_3.STL" />
      </geometry>
      <material
        name="">
        <color
          rgba="1 1 1 1" />
      </material>
    </visual>
    <collision>
      <origin
        xyz="0 0 0"
        rpy="0 0 0" />
      <geometry>
        <mesh
          filename="package://planar_robot/meshes/link_3.STL" />
      </geometry>
    </collision>
  </link>
  <joint
    name="joint_3"
    type="continuous">
    <origin
      xyz="0.4 0 0"
      rpy="0 0 0" />
    <parent
      link="link_2" />
    <child
      link="link_3" />
    <axis
      xyz="0 1 0" />
    <limit
      lower="-6.28"
      upper="6.28"
      effort="0"
      velocity="0" />
  </joint>
  <link
    name="link_ee">
    <inertial>
      <origin
        xyz="0.031684 0.0125 -2.7756E-17"
        rpy="0 0 0" />
      <mass
        value="0.22207" />
      <inertia
        ixx="0.00032831"
        ixy="5.2816E-21"
        ixz="1.3891E-19"
        iyy="0.00056864"
        iyz="3.089E-21"
        izz="0.00026346" />
    </inertial>
    <visual>
      <origin
        xyz="0 0 0"
        rpy="0 0 0" />
      <geometry>
        <mesh
          filename="package://planar_robot/meshes/link_ee.STL" />
      </geometry>
      <material
        name="">
        <color
          rgba="0.8 1 0.8 1" />
      </material>
    </visual>
    <collision>
      <origin
        xyz="0 0 0"
        rpy="0 0 0" />
      <geometry>
        <mesh
          filename="package://planar_robot/meshes/link_ee.STL" />
      </geometry>
    </collision>
  </link>
  <joint
    name="joint_ee"
    type="fixed">
    <origin
      xyz="0.1 0 0"
      rpy="0 0 0" />
    <parent
      link="link_3" />
    <child
      link="link_ee" />
    <axis
      xyz="0 0 0" />
  </joint>
</robot>
