<?xml version="1.0" ?>
<!-- =================================================================================== -->
<!-- |    This document was autogenerated by xacro from ./jaka_dual.xacro              | -->
<!-- |    EDITING THIS FILE BY HAND IS NOT RECOMMENDED                                 | -->
<!-- =================================================================================== -->
<robot name="dual">
  <material name="white">
    <color rgba="0.6 1 1 1"/>
  </material>
  <material name="gripper_color">
    <color rgba="0.2 0.6 0.8 0.75"/>
  </material>
  <material name="platform_color">
    <color rgba="1 0.6 0 0.9"/>
  </material>
  <link name="left_base_link">
    <visual>
      <!--origin rpy="0 ${pi / 2} 0" xyz="0 0 0.0198"/>-->
      <origin rpy="0 0 -1.5707963267948966" xyz="0 0 -0.0005"/>
      <geometry>
        <mesh filename="package://zu7/mesh/p11.dae"/>
      </geometry>
      <material name="white">
        <color rgba="1 1 1 1"/>
      </material>
    </visual>
    <collision>
      <geometry>
        <mesh filename="package://zu7/mesh/p11.dae"/>
      </geometry>
      <origin rpy="0 0 0" xyz="0 0 -0.0005"/>
    </collision>
  </link>
  <link name="left_link_1">
    <visual>
      <geometry>
        <mesh filename="package://zu7/mesh/p22.dae"/>
      </geometry>
      <material name="white">
        <color rgba="1 1 1 1"/>
      </material>
      <!--origin rpy=" ${pi/2.0}  0  ${pi/2.0}" xyz="0 0 0"/>-->
      <origin rpy="0 0 0" xyz="0 0 0"/>
    </visual>
    <collision>
      <geometry>
        <mesh filename="package://zu7/mesh/p22.dae"/>
      </geometry>
      <origin rpy="0 0 0" xyz="0 0 0"/>
    </collision>
    <inertial>
      <origin xyz="0.0 0.0 0.0" rpy="0.0 0.0 0.0"/>
      <mass value="8"/>
      <inertia ixx="0.3" ixy="0.0" ixz="0.0" iyy="0.3" iyz="0.0" izz="0.2"/>
    </inertial>
  </link>
  <joint name="left_joint_1" type="revolute">
    <axis xyz="0 0 1"/>
    <limit effort="1000" lower="-4.963716393" upper="4.963716393" velocity="3.14"/>
    <origin rpy="0 0 0" xyz="0 0 0.114"/>
    <parent link="left_base_link"/>
    <child link="left_link_1"/>
  </joint>
  <link name="left_link_2">
    <visual>
      <geometry>
        <mesh filename="package://zu7/mesh/p35.dae"/>
      </geometry>
      <!--origin rpy="${pi/2.0}  ${pi} ${pi/2.0}" xyz="-0.1595 0 -0.115"/>-->
      <material name="white">
        <color rgba="1 1 1 1"/>
      </material>
      <origin rpy="1.5707963267948966 3.141592653589793 1.5707963267948966" xyz="0 0 0.01 "/>
      <material name="white">
        <color rgba="1 1 1 1"/>
      </material>
    </visual>
    <collision>
      <geometry>
        <mesh filename="package://zu7/mesh/p35.dae"/>
      </geometry>
      <origin rpy="1.5707963267948966 3.141592653589793 1.5707963267948966" xyz="0 0 0.01 "/>
    </collision>
    <inertial>
      <mass value="6"/>
      <inertia ixx="0.25" ixy="0.0" ixz="0.0" iyy="0.25" iyz="0.0" izz="0.15"/>
    </inertial>
  </link>
  <joint name="left_joint_2" type="revolute">
    <axis xyz="0 0 1"/>
    <limit effort="1000" lower="-1.171988593" upper="3.653846789" velocity="3.14"/>
    <origin rpy="1.5707963267948966 0 0" xyz="0 0.005 0"/>
    <parent link="left_link_1"/>
    <child link="left_link_2"/>
  </joint>
  <link name="left_link_3">
    <visual>
      <geometry>
        <mesh filename="package://zu7/mesh/p44.dae"/>
      </geometry>
      <material name="white">
        <color rgba="1 1 1 1"/>
      </material>
      <origin rpy="-1.5707963267948966 0 -1.5707963267948966" xyz="0.303 0 -0.013"/>
    </visual>
    <collision>
      <geometry>
        <mesh filename="package://zu7/mesh/p44.dae"/>
      </geometry>
      <origin rpy="-1.5707963267948966 0 -1.5707963267948966" xyz="0.303 0 -0.013"/>
    </collision>
    <inertial>
      <mass value="8"/>
      <inertia ixx="0.3" ixy="0.0" ixz="0.0" iyy="0.3" iyz="0.0" izz="0.2"/>
    </inertial>
  </link>
  <joint name="left_joint_3" type="revolute">
    <axis xyz="0 0 1"/>
    <limit effort="1000" lower="-2.412917691" upper="2.412917691" velocity="3.14"/>
    <origin rpy="0 0 0" xyz="0.353 0 0.005"/>
    <parent link="left_link_2"/>
    <child link="left_link_3"/>
  </joint>
  <link name="left_link_4">
    <visual>
      <geometry>
        <mesh filename="package://zu7/mesh/p55.dae"/>
      </geometry>
      <origin rpy="1.5707963267948966 0 1.5707963267948966" xyz="0.00 0 0.00"/>
      <material name="white">
        <color rgba="1 1 1 1"/>
      </material>
    </visual>
    <collision>
      <geometry>
        <mesh filename="package://zu7/mesh/p55.dae"/>
      </geometry>
      <origin rpy="1.5707963267948966 0 1.5707963267948966" xyz="0.00 0 0.00"/>
    </collision>
    <inertial>
      <mass value="5"/>
      <inertia ixx="0.2" ixy="0.0" ixz="0.0" iyy="0.2" iyz="0.0" izz="0.15"/>
    </inertial>
  </link>
  <joint name="left_joint_4" type="revolute">
    <axis xyz="0 0 1"/>
    <limit effort="1000" lower="-1.171988593" upper="3.653846789" velocity="3.14"/>
    <origin rpy="0 0 0" xyz="0.303 0 -0.1155"/>
    <parent link="left_link_3"/>
    <child link="left_link_4"/>
  </joint>
  <link name="left_link_5">
    <visual>
      <geometry>
        <mesh filename="package://zu7/mesh/p66.dae"/>
      </geometry>
      <origin rpy="3.141592653589793 0 -1.5707963267948966" xyz="0 0 0"/>
      <material name="">
        <color rgba="1 0.1 0.1 1"/>
      </material>
    </visual>
    <collision>
      <geometry>
        <mesh filename="package://zu7/mesh/p66.dae"/>
      </geometry>
      <origin rpy="3.141592653589793 0 -1.5707963267948966" xyz="0 0 0"/>
    </collision>
    <inertial>
      <mass value="4"/>
      <inertia ixx="0.1" ixy="0.0" ixz="0.0" iyy="0.1" iyz="0.0" izz="0.07"/>
    </inertial>
  </link>
  <joint name="left_joint_5" type="revolute">
    <axis xyz="0 0 1"/>
    <limit effort="1000" lower="-4.963716393" upper="4.963716393" velocity="3.14"/>
    <origin rpy="1.5707963267948966 0 0" xyz="0 -0.1025 0"/>
    <parent link="left_link_4"/>
    <child link="left_link_5"/>
  </joint>
  <link name="left_link_6">
    <visual>
      <geometry>
        <mesh filename="package://zu7/mesh/p77.dae"/>
      </geometry>
      <origin rpy="0 -1.5707963267948966 0" xyz="0 0 0"/>
    </visual>
    <collision>
      <geometry>
        <mesh filename="package://zu7/mesh/p77.dae"/>
      </geometry>
      <origin rpy="0 -1.5707963267948966 0" xyz="0 0 0"/>
    </collision>
    <inertial>
      <mass value="2"/>
      <inertia ixx="0.07" ixy="0.0" ixz="0.0" iyy="0.07" iyz="0.0" izz="0.04"/>
    </inertial>
  </link>
  <joint name="left_joint_6" type="revolute">
    <axis xyz="0 0 1"/>
    <limit effort="1000" lower="-4.963716393" upper="4.963716393" velocity="3.14"/>
    <origin rpy="-1.5707963267948966 0 0" xyz="0 0.0595 0"/>
    <parent link="left_link_5"/>
    <child link="left_link_6"/>
  </joint>
  <link name="right_base_link">
    <inertial>
      <origin rpy="0 0 0" xyz="0.000965034909848577 0.0195530292148323 -7.27080869111029E-08"/>
      <mass value="0.514609969031532"/>
      <inertia ixx="0.000621364399247646" ixy="3.21692650554867E-06" ixz="-3.71184934823013E-09" iyy="0.0013529358522947" iyz="3.8977685173265E-11" izz="0.00086645249213919"/>
    </inertial>
    <visual>
      <origin rpy="0 0 0" xyz="0 0 0"/>
      <geometry>
        <mesh filename="package://jaka_zu7_v2/meshes/base_link.STL"/>
      </geometry>
      <material name="">
        <color rgba="1 1 1 1"/>
      </material>
    </visual>
    <collision>
      <origin rpy="0 0 0" xyz="0 0 0"/>
      <geometry>
        <mesh filename="package://jaka_zu7_v2/meshes/base_link.STL"/>
      </geometry>
    </collision>
  </link>
  <link name="right_link_1">
    <inertial>
      <origin rpy="0 0 0" xyz="0.00332253130665769 0.0786385509598458 5.2958727998931E-08"/>
      <mass value="1.92821258656447"/>
      <inertia ixx="0.00548947482538057" ixy="1.93161087253844E-06" ixz="-2.06406149519604E-08" iyy="0.00388876051174381" iyz="-1.29468636322429E-08" izz="0.00564332197967477"/>
    </inertial>
    <visual>
      <origin rpy="0 0 0" xyz="0 0 0"/>
      <geometry>
        <mesh filename="package://jaka_zu7_v2/meshes/link_1.STL"/>
      </geometry>
      <material name="">
        <color rgba="1 0 0 1"/>
      </material>
    </visual>
    <collision>
      <origin rpy="0 0 0" xyz="0 0 0"/>
      <geometry>
        <mesh filename="package://jaka_zu7_v2/meshes/link_1.STL"/>
      </geometry>
    </collision>
  </link>
  <joint name="right_joint_1" type="revolute">
    <origin rpy="1.5707963267949 0 1.5707963267949" xyz="0 0 0.04"/>
    <parent link="right_base_link"/>
    <child link="right_link_1"/>
    <axis xyz="0 1 0"/>
    <limit effort="0" lower="-4.963716393" upper="4.963716393" velocity="3.14"/>
  </joint>
  <link name="right_link_2">
    <inertial>
      <origin rpy="0 0 0" xyz="0.179999937405946 0.0790752745504925 9.75081933252131E-09"/>
      <mass value="5.46179073513085"/>
      <inertia ixx="0.0129179479280493" ixy="-2.71044464180044E-08" ixz="-1.50487643543411E-08" iyy="0.138149394009534" iyz="-2.73361042997731E-09" izz="0.141659548589032"/>
    </inertial>
    <visual>
      <origin rpy="0 0 0" xyz="0 0 0"/>
      <geometry>
        <mesh filename="package://jaka_zu7_v2/meshes/link_2.STL"/>
      </geometry>
      <material name="">
        <color rgba="1 1 1 1"/>
      </material>
    </visual>
    <collision>
      <origin rpy="0 0 0" xyz="0 0 0"/>
      <geometry>
        <mesh filename="package://jaka_zu7_v2/meshes/link_2.STL"/>
      </geometry>
    </collision>
  </link>
  <joint name="right_joint_2" type="revolute">
    <origin rpy="-1.5707963267949 -1.5707963267949 0" xyz="0.064 0.0801499805565675 0"/>
    <parent link="right_link_1"/>
    <child link="right_link_2"/>
    <axis xyz="0 -1 0"/>
    <limit effort="0" lower="-1.171988593" upper="3.653846789" velocity="3.14"/>
  </joint>
  <link name="right_link_3">
    <inertial>
      <origin rpy="0 0 0" xyz="0.155128159726302 0.0514243418134301 -2.21667684600496E-05"/>
      <mass value="2.10988248004298"/>
      <inertia ixx="0.00267097214313929" ixy="-0.00234320623456127" ixz="2.68932154375193E-07" iyy="0.0354758560218789" iyz="-5.66886998256416E-09" izz="0.0361345568869166"/>
    </inertial>
    <visual>
      <origin rpy="0 0 0" xyz="0 0 0"/>
      <geometry>
        <mesh filename="package://jaka_zu7_v2/meshes/link_3.STL"/>
      </geometry>
      <material name="">
        <color rgba="1 1 1 1"/>
      </material>
    </visual>
    <collision>
      <origin rpy="0 0 0" xyz="0 0 0"/>
      <geometry>
        <mesh filename="package://jaka_zu7_v2/meshes/link_3.STL"/>
      </geometry>
    </collision>
  </link>
  <joint name="right_joint_3" type="revolute">
    <origin rpy="3.14159265358979 0 0" xyz="0.36 0 0"/>
    <parent link="right_link_2"/>
    <child link="right_link_3"/>
    <axis xyz="0 1 0"/>
    <limit effort="0" lower="-2.412917691" upper="2.412917691" velocity="3.14"/>
  </joint>
  <link name="right_link_4">
    <inertial>
      <origin rpy="0 0 0" xyz="0.0428277143121445 -0.00580000262750839 -2.15426459782009E-07"/>
      <mass value="0.707389472258975"/>
      <inertia ixx="0.00114244205941306" ixy="1.06377457242975E-05" ixz="-1.00655969113403E-08" iyy="0.000665673392092465" iyz="4.52474533922176E-09" izz="0.00117908344473012"/>
    </inertial>
    <visual>
      <origin rpy="0 0 0" xyz="0 0 0"/>
      <geometry>
        <mesh filename="package://jaka_zu7_v2/meshes/link_4.STL"/>
      </geometry>
      <material name="">
        <color rgba="1 1 1 1"/>
      </material>
    </visual>
    <collision>
      <origin rpy="0 0 0" xyz="0 0 0"/>
      <geometry>
        <mesh filename="package://jaka_zu7_v2/meshes/link_4.STL"/>
      </geometry>
    </collision>
  </link>
  <joint name="right_joint_4" type="revolute">
    <origin rpy="-1.5707963267949 0 -1.5707963267949" xyz="0.3035 -0.00551249887704253 0"/>
    <parent link="right_link_3"/>
    <child link="right_link_4"/>
    <axis xyz="-1 0 0"/>
    <limit effort="0" lower="-1.171988593" upper="3.653846789" velocity="3.14"/>
  </joint>
  <link name="right_link_5">
    <inertial>
      <origin rpy="0 0 0" xyz="-0.0431572815381937 0.00288955773134447 1.49710568941863E-07"/>
      <mass value="0.806937512326124"/>
      <inertia ixx="0.0016178075971003" ixy="5.79122309605624E-06" ixz="-2.27237716815389E-08" iyy="0.000744722110552353" iyz="6.4924718539349E-10" izz="0.00165512070235347"/>
    </inertial>
    <visual>
      <origin rpy="0 0 0" xyz="0 0 0"/>
      <geometry>
        <mesh filename="package://jaka_zu7_v2/meshes/link_5.STL"/>
      </geometry>
      <material name="">
        <color rgba="1 0.1 0.1 1"/>
      </material>
    </visual>
    <collision>
      <origin rpy="0 0 0" xyz="0 0 0"/>
      <geometry>
        <mesh filename="package://jaka_zu7_v2/meshes/link_5.STL"/>
      </geometry>
    </collision>
  </link>
  <joint name="right_joint_5" type="revolute">
    <origin rpy="3.141592653589793 0 1.5707963267949" xyz="0.0455 -0.068 0"/>
    <parent link="right_link_4"/>
    <child link="right_link_5"/>
    <axis xyz="-1 0 0"/>
    <limit effort="0" lower="-4.963716393" upper="4.963716393" velocity="3.14"/>
  </joint>
  <link name="right_link_6">
    <inertial>
      <origin rpy="-1.5707963267948966 0 0" xyz="-1.97890204940432E-05 -0.0177548861304407 2.35655774806776E-05"/>
      <mass value="0.180494479521819"/>
      <inertia ixx="9.15750415659571E-05" ixy="-3.15858980075031E-08" ixz="1.86044178570153E-07" iyy="0.000144413544278706" iyz="1.29636476465431E-07" izz="9.21528525921217E-05"/>
    </inertial>
    <visual>
      <origin rpy="-1.5707963267948966 0 0" xyz="0 0 0"/>
      <geometry>
        <mesh filename="package://jaka_zu7_v2/meshes/link_6.STL"/>
      </geometry>
      <material name="">
        <color rgba="1 1 1 1"/>
      </material>
    </visual>
    <collision>
      <origin rpy="-1.5707963267948966 0 0" xyz="0 0 0"/>
      <geometry>
        <mesh filename="package://jaka_zu7_v2/meshes/link_6.STL"/>
      </geometry>
    </collision>
  </link>
  <joint name="right_joint_6" type="revolute">
    <origin rpy="1.5707963267948966 1.5707963267948966 0" xyz="-0.0455 -0.068 0"/>
    <parent link="right_link_5"/>
    <child link="right_link_6"/>
    <axis xyz="0 0 1"/>
    <limit effort="0" lower="-4.963716393" upper="4.963716393" velocity="3.14"/>
  </joint>
  <joint name="left_to_right" type="fixed">
    <parent link="right_base_link"/>
    <child link="left_base_link"/>
    <origin rpy="-0.015272913100903103 0.01866994910995618 0.02274242853030429" xyz="0.48622462  0.0084934  -0.00136687"/>
  </joint>
  <link name="right_gripper_base_link">
    <visual>
      <geometry>
        <mesh filename="package://jaka_zu7_v2/meshes/gripper-raw.STL"/>
      </geometry>
      <material name="gripper_color"/>
    </visual>
    <collision>
      <geometry>
        <mesh filename="package://jaka_zu7_v2/meshes/gripper-raw.STL"/>
      </geometry>
    </collision>
  </link>
  <joint name="right_ee_joint" type="fixed">
    <parent link="right_link_6"/>
    <child link="right_gripper_base_link"/>
    <origin rpy="0 0 0" xyz="0 0 0.039"/>
  </joint>
  <link name="left_gripper_base_link">
    <visual>
      <geometry>
        <mesh filename="package://jaka_zu7_v2/meshes/gripper-raw.STL"/>
      </geometry>
      <material name="gripper_color"/>
    </visual>
    <collision>
      <geometry>
        <mesh filename="package://jaka_zu7_v2/meshes/gripper-raw.STL"/>
      </geometry>
    </collision>
  </link>
  <joint name="left_ee_joint" type="fixed">
    <parent link="left_link_6"/>
    <child link="left_gripper_base_link"/>
    <origin rpy="0 0 0" xyz="0 0 0.0355"/>
  </joint>
  <link name="platform">
    <visual>
      <geometry>
        <box size="1.2 0.6 0.6"/>
      </geometry>
      <material name="platform_color"/>
      <origin xyz="0.0 0.0 0.0"/>
    </visual>
    <collision>
      <geometry>
        <box size="1.2 0.6 0.6"/>
      </geometry>
      <origin xyz="0.0 0.0 0.0"/>
    </collision>
    <inertial>
      <origin xyz="0.0 0.0 0.0" rpy="0.0 0.0 0.0"/>
      <mass value="500"/>
      <inertia ixx="30" ixy="0.0" ixz="0.0" iyy="75" iyz="0.0" izz="75"/>
    </inertial>
  </link>
  <joint name="right_to_platform" type="fixed">
    <parent link="platform"/>
    <child link="right_base_link"/>
    <origin xyz="-0.4 0.1 0.3"/>
  </joint>

</robot>
